Workbook

Sheet Mode d'emploi
B2: Strategie de descente, version 2026
B3: Reconstruction du tableau d'origine sur les prix et la volatilite d'aujourd'hui. L'ancien fichier n'a pas ete modifie.
B6: CE QUI A CHANGE, ET POURQUOI
B7: 1. Les prix de reference etaient perimes.
B8: Sept de vos neuf pieces ont perdu plus de la moitie de leur valeur depuis la derniere mise a jour, deux d'entre elles 90 %. Deux ont monte. Les references du classeur sont desormais les prix reels du jour, releves sur Binance. La feuille Reglages les affiche a cote des anciennes.
B9: 2. Les paliers sont en pourcentage, plus en valeur absolue.
B10: L'ancien tableau descendait par pas fixes (0,15 pour XRP). Sur une piece a 0,21 aujourd'hui, un pas de 0,15 n'a plus de sens, et l'ancienne feuille finissait d'ailleurs par afficher des prix negatifs. Tout est maintenant relatif au prix de reference, donc valable a n'importe quel niveau de cours.
B11: 3. Les echelles sont plus profondes et plus nombreuses.
B12: Vos echelles couvraient en moyenne 8 % de baisse, celle de XRP seulement 4,5 %. J'ai mesure sur un an la profondeur reelle des episodes de baisse de chaque piece, et dimensionne chaque echelle sur le troisieme quartile : trois episodes sur quatre sont desormais absorbes entierement. Dix a douze paliers au lieu de cinq.
B13: 4. La progression des mises est plus douce.
B14: Vous doubliez, voire multipliiez par 2,5 a chaque palier. La derniere mise pesait alors plus de la moitie du budget. Le classeur utilise 1,8 par defaut : le rebond necessaire passe de 4 a 5,5 %, mais l'echelle va deux fois plus profond pour le meme argent. Le reglage reste modifiable.
B15: 5. Les frais sont dans l'objectif.
... B30: La strategie gagne souvent et perd rarement, mais elle perd gros quand elle perd. Un objectif de 2 % repete ne compense pas une piece qui ne revient jamais. Sur vos neuf pieces, l'historique d'un an montre des baisses maximales de 24 % a 85 % selon la piece. Aucun reglage de tableau ne protege de cela : seuls le budget global et la regle d'abandon le font.

Sheet Tableau de bord
A1: Tableau de bord
A2: Etat des neuf descentes. Mettez a jour le prix actuel dans chaque feuille.
A4: Crypto | B4: Prix actuel | C4: Investi (EUR) | D4: Budget prevu | E4: Unites | F4: Prix de revient | G4: Prix de revente | H4: Rebond requis | I4: P&L latent | J4: Gain si revendu | K4: Jours | L4: Etat
A5: AAVE | B5: ='AAVE'!B9 | C5: ='AAVE'!F27 | D5: ='AAVE'!C27 | E5: ='AAVE'!G27 | F5: ='AAVE'!J27 | G5: ='AAVE'!K27 | H5: ='AAVE'!N27 | I5: ='AAVE'!M27 | J5: ='AAVE'!E29 | K5: ='AAVE'!E5 | L5: ='AAVE'!E30
A6: ADA | B6: ='ADA'!B9 | C6: ='ADA'!F27 | D6: ='ADA'!C27 | E6: ='ADA'!G27 | F6: ='ADA'!J27 | G6: ='ADA'!K27 | H6: ='ADA'!N27 | I6: ='ADA'!M27 | J6: ='ADA'!E29 | K6: ='ADA'!E5 | L6: ='ADA'!E30
A7: BCH | B7: ='BCH'!B9 | C7: ='BCH'!F27 | D7: ='BCH'!C27 | E7: ='BCH'!G27 | F7: ='BCH'!J27 | G7: ='BCH'!K27 | H7: ='BCH'!N27 | I7: ='BCH'!M27 | J7: ='BCH'!E29 | K7: ='BCH'!E5 | L7: ='BCH'!E30
A8: DGB | B8: ='DGB'!B9 | C8: ='DGB'!F27 | D8: ='DGB'!C27 | E8: ='DGB'!G27 | F8: ='DGB'!J27 | G8: ='DGB'!K27 | H8: ='DGB'!N27 | I8: ='DGB'!M27 | J8: ='DGB'!E29 | K8: ='DGB'!E5 | L8: ='DGB'!E30
A9: DOGE | B9: ='DOGE'!B9 | C9: ='DOGE'!F27 | D9: ='DOGE'!C27 | E9: ='DOGE'!G27 | F9: ='DOGE'!J27 | G9: ='DOGE'!K27 | H9: ='DOGE'!N27 | I9: ='DOGE'!M27 | J9: ='DOGE'!E29 | K9: ='DOGE'!E5 | L9: ='DOGE'!E30
A10: ETH | B10: ='ETH'!B9 | C10: ='ETH'!F27 | D10: ='ETH'!C27 | E10: ='ETH'!G27 | F10: ='ETH'!J27 | G10: ='ETH'!K27 | H10: ='ETH'!N27 | I10: ='ETH'!M27 | J10: ='ETH'!E29 | K10: ='ETH'!E5 | L10: ='ETH'!E30
A11: TRX | B11: ='TRX'!B9 | C11: ='TRX'!F27 | D11: ='TRX'!C27 | E11: ='TRX'!G27 | F11: ='TRX'!J27 | G11: ='TRX'!K27 | H11: ='TRX'!N27 | I11: ='TRX'!M27 | J11: ='TRX'!E29 | K11: ='TRX'!E5 | L11: ='TRX'!E30
A12: UNI | B12: ='UNI'!B9 | C12: ='UNI'!F27 | D12: ='UNI'!C27 | E12: ='UNI'!G27 | F12: ='UNI'!J27 | G12: ='UNI'!K27 | H12: ='UNI'!N27 | I12: ='UNI'!M27 | J12: ='UNI'!E29 | K12: ='UNI'!E5 | L12: ='UNI'!E30
A13: XRP | B13: ='XRP'!B9 | C13: ='XRP'!F27 | D13: ='XRP'!C27 | E13: ='XRP'!G27 | F13: ='XRP'!J27 | G13: ='XRP'!K27 | H13: ='XRP'!N27 | I13: ='XRP'!M27 | J13: ='XRP'!E29 | K13: ='XRP'!E5 | L13: ='XRP'!E30
A14: TOTAL | C14: =SUM(C5:C13) | D14: =SUM(D5:D13) | I14: =SUM(I5:I13) | J14: =SUM(J5:J13)

Sheet Reglages
A1: Reglages
A2: Les cellules jaunes sont modifiables. Tout le classeur en depend.
A4: Reglages generaux
A5: Frais Binance par ordre | B5: 0.001 | C5: 0,1 % au comptant. Comptez 5 achats et 1 vente par descente.
A6: Objectif de gain NET a la revente | B6: 0.02 | C6: Net de frais. Le prix de revente en tient compte.
A7: Capital total que vous acceptez d'engager | B7: 20000 | C7: Plafond global. La feuille Risque compare la somme des budgets a ce plafond.
A8: Jours avant de declarer une descente bloquee | B8: 30 | C8: Au-dela, le tableau de bord signale la ligne.
A11: Reglages par crypto
A12: Crypto | B12: Prix de reference (a mettre a jour) | C12: Ancien prix du tableau | D12: Ecart | E12: Budget alloue (EUR) | F12: Profondeur de l'echelle | G12: Nombre de paliers | H12: Progression des mises | I12: Pas entre paliers | J12: Dernier palier | K12: Rebond requis depuis le bas | L12: Baisse p75 mesuree | M12: Pire baisse sur 1 an
A13: AAVE | B13: 133.75 | C13: 300 | D13: =B13/C13-1 | E13: 1500 | F13: 0.146 | G13: 10 | H13: 1.8 | I13: =F13/(G13-1) | J13: =B13*(1-F13) | K13: =SUMPRODUCT($H13^(ROW(INDIRECT("1:"&$G13))-1))/((1-$B$5)*SUMPRODUCT($H13^(ROW(INDIRECT("1:"&$G13))-1)/($B13*(1-$I13*(ROW(INDIRECT("1:"&$G13))-1)))))*(1+$B$6)/(1-$B$5)/$J13-1 | L13: 0.1464 | M13: 0.8202
A14: ADA | B14: 0.2173 | C14: 2.5 | D14: =B14/C14-1 | E14: 1500 | F14: 0.114 | G14: 10 | H14: 1.8 | I14: =F14/(G14-1) | J14: =B14*(1-F14) | K14: =SUMPRODUCT($H14^(ROW(INDIRECT("1:"&$G14))-1))/((1-$B$5)*SUMPRODUCT($H14^(ROW(INDIRECT("1:"&$G14))-1)/($B14*(1-$I14*(ROW(INDIRECT("1:"&$G14))-1)))))*(1+$B$6)/(1-$B$5)/$J14-1 | L14: 0.114 | M14: 0.8513
A15: BCH | B15: 256.6 | C15: 548 | D15: =B15/C15-1 | E15: 1500 | F15: 0.1 | G15: 10 | H15: 1.8 | I15: =F15/(G15-1) | J15: =B15*(1-F15) | K15: =SUMPRODUCT($H15^(ROW(INDIRECT("1:"&$G15))-1))/((1-$B$5)*SUMPRODUCT($H15^(ROW(INDIRECT("1:"&$G15))-1)/($B15*(1-$I15*(ROW(INDIRECT("1:"&$G15))-1)))))*(1+$B$6)/(1-$B$5)/$J15-1 | L15: 0.0955 | M15: 0.7235
A16: DGB | B16: 0.00507 | C16: 0.05 | D16: =B16/C16-1 | E16: 1500 | F16: 0.192 | G16: 12 | H16: 1.8 | I16: =F16/(G16-1) | J16: =B16*(1-F16) | K16: =SUMPRODUCT($H16^(ROW(INDIRECT("1:"&$G16))-1))/((1-$B$5)*SUMPRODUCT($H16^(ROW(INDIRECT("1:"&$G16))-1)/($B16*(1-$I16*(ROW(INDIRECT("1:"&$G16))-1)))))*(1+$B$6)/(1-$B$5)/$J16-1 | L16: 0.1917 | M16: 0.7833
A17: DOGE | B17: 0.08891 | C17: 0.29 | D17: =B17/C17-1 | E17: 1500 | F17: 0.102 | G17: 10 | H17: 1.8 | I17: =F17/(G17-1) | J17: =B17*(1-F17) | K17: =SUMPRODUCT($H17^(ROW(INDIRECT("1:"&$G17))-1))/((1-$B$5)*SUMPRODUCT($H17^(ROW(INDIRECT("1:"&$G17))-1)/($B17*(1-$I17*(ROW(INDIRECT("1:"&$G17))-1)))))*(1+$B$6)/(1-$B$5)/$J17-1 | L17: 0.1018 | M17: 0.7662
A18: ETH | B18: 2484.1 | C18: 2648 | D18: =B18/C18-1 | E18: 1500 | F18: 0.136 | G18: 10 | H18: 1.8 | I18: =F18/(G18-1) | J18: =B18*(1-F18) | K18: =SUMPRODUCT($H18^(ROW(INDIRECT("1:"&$G18))-1))/((1-$B$5)*SUMPRODUCT($H18^(ROW(INDIRECT("1:"&$G18))-1)/($B18*(1-$I18*(ROW(INDIRECT("1:"&$G18))-1)))))*(1+$B$6)/(1-$B$5)/$J18-1 | L18: 0.1363 | M18: 0.6805
A19: TRX | B19: 0.3351 | C19: 0.046 | D19: =B19/C19-1 | E19: 1500 | F19: 0.1 | G19: 10 | H19: 1.8 | I19: =F19/(G19-1) | J19: =B19*(1-F19) | K19: =SUMPRODUCT($H19^(ROW(INDIRECT("1:"&$G19))-1))/((1-$B$5)*SUMPRODUCT($H19^(ROW(INDIRECT("1:"&$G19))-1)/($B19*(1-$I19*(ROW(INDIRECT("1:"&$G19))-1)))))*(1+$B$6)/(1-$B$5)/$J19-1 | L19: 0.0452 | M19: 0.2389
A20: UNI | B20: 6.936 | C20: 18.9 | D20: =B20/C20-1 | E20: 1500 | F20: 0.248 | G20: 12 | H20: 1.8 | I20: =F20/(G20-1) | J20: =B20*(1-F20) | K20: =SUMPRODUCT($H20^(ROW(INDIRECT("1:"&$G20))-1))/((1-$B$5)*SUMPRODUCT($H20^(ROW(INDIRECT("1:"&$G20))-1)/($B20*(1-$I20*(ROW(INDIRECT("1:"&$G20))-1)))))*(1+$B$6)/(1-$B$5)/$J20-1 | L20: 0.2477 | M20: 0.8035
A21: XRP | B21: 1.4096 | C21: 0.89 | D21: =B21/C21-1 | E21: 1500 | F21: 0.125 | G21: 10 | H21: 1.8 | I21: =F21/(G21-1) | J21: =B21*(1-F21) | K21: =SUMPRODUCT($H21^(ROW(INDIRECT("1:"&$G21))-1))/((1-$B$5)*SUMPRODUCT($H21^(ROW(INDIRECT("1:"&$G21))-1)/($B21*(1-$I21*(ROW(INDIRECT("1:"&$G21))-1)))))*(1+$B$6)/(1-$B$5)/$J21-1 | L21: 0.1251 | M21: 0.6838
A23: Profondeur en orange : elle est plus courte que trois episodes de baisse sur quatre observes sur un an. Ecart en rouge : la piece a perdu plus de la moitie de sa valeur depuis l'ancien tableau.

Sheet AAVE
A1: Descente AAVE
A2: Colonnes jaunes : a remplir quand l'achat est passe. Le reste est calcule.
A4: Prix de reference | B4: =Reglages!B13 | D4: Date du premier achat
A5: Budget alloue | B5: =Reglages!E13 | D5: Jours ecoules | E5: =IF(E4="","",TODAY()-E4)
A6: Profondeur de l'echelle | B6: =Reglages!F13 | D6: Seuil d'abandon | E6: =B7*(1-0.15) | F6: 15 % sous le dernier palier. En dessous, on n'ajoute plus rien.
A7: Prix du dernier palier | B7: =Reglages!J13
A8: Objectif net a la revente | B8: =Reglages!B6
A9: Prix actuel du marche | B9: 133.75
A12: Palier | B12: Prix cible | C12: Mise prevue (EUR) | D12: Fait ? (1 = oui) | E12: Prix reellement paye | F12: Montant reellement investi (EUR) | G12: Unites obtenues | H12: Cumul investi | I12: Cumul unites | J12: Prix de revient moyen | K12: Prix de revente (+2 % net) | L12: Valeur au prix actuel | M12: P&L latent | N12: Rebond requis depuis ce palier
A13: 1 | B13: =IF(1>Reglages!$G$13,"",$B$4*(1-Reglages!$I$13*0)) | C13: =IF(1>Reglages!$G$13,"",$B$5*Reglages!$H$13^0/SUMPRODUCT(Reglages!$H$13^(ROW(INDIRECT("1:"&Reglages!$G$13))-1))) | G13: =IF(OR(D13<>1,E13="",E13=0),0,F13/E13*(1-Reglages!$B$5)) | H13: =SUM($F$13:F13) | I13: =SUM($G$13:G13) | J13: =IF(I13=0,"",H13/I13) | K13: =IF(I13=0,"",J13*(1+$B$8)/(1-Reglages!$B$5)) | L13: =I13*$B$9 | M13: =IF(I13=0,"",L13-H13) | N13: =IF(OR(I13=0,B13=""),"",K13/B13-1)
A14: 2 | B14: =IF(2>Reglages!$G$13,"",$B$4*(1-Reglages!$I$13*1)) | C14: =IF(2>Reglages!$G$13,"",$B$5*Reglages!$H$13^1/SUMPRODUCT(Reglages!$H$13^(ROW(INDIRECT("1:"&Reglages!$G$13))-1))) | G14: =IF(OR(D14<>1,E14="",E14=0),0,F14/E14*(1-Reglages!$B$5)) | H14: =SUM($F$13:F14) | I14: =SUM($G$13:G14) | J14: =IF(I14=0,"",H14/I14) | K14: =IF(I14=0,"",J14*(1+$B$8)/(1-Reglages!$B$5)) | L14: =I14*$B$9 | M14: =IF(I14=0,"",L14-H14) | N14: =IF(OR(I14=0,B14=""),"",K14/B14-1)
A15: 3 | B15: =IF(3>Reglages!$G$13,"",$B$4*(1-Reglages!$I$13*2)) | C15: =IF(3>Reglages!$G$13,"",$B$5*Reglages!$H$13^2/SUMPRODUCT(Reglages!$H$13^(ROW(INDIRECT("1:"&Reglages!$G$13))-1))) | G15: =IF(OR(D15<>1,E15="",E15=0),0,F15/E15*(1-Reglages!$B$5)) | H15: =SUM($F$13:F15) | I15: =SUM($G$13:G15) | J15: =IF(I15=0,"",H15/I15) | K15: =IF(I15=0,"",J15*(1+$B$8)/(1-Reglages!$B$5)) | L15: =I15*$B$9 | M15: =IF(I15=0,"",L15-H15) | N15: =IF(OR(I15=0,B15=""),"",K15/B15-1)
A16: 4 | B16: =IF(4>Reglages!$G$13,"",$B$4*(1-Reglages!$I$13*3)) | C16: =IF(4>Reglages!$G$13,"",$B$5*Reglages!$H$13^3/SUMPRODUCT(Reglages!$H$13^(ROW(INDIRECT("1:"&Reglages!$G$13))-1))) | G16: =IF(OR(D16<>1,E16="",E16=0),0,F16/E16*(1-Reglages!$B$5)) | H16: =SUM($F$13:F16) | I16: =SUM($G$13:G16) | J16: =IF(I16=0,"",H16/I16) | K16: =IF(I16=0,"",J16*(1+$B$8)/(1-Reglages!$B$5)) | L16: =I16*$B$9 | M16: =IF(I16=0,"",L16-H16) | N16: =IF(OR(I16=0,B16=""),"",K16/B16-1)
A17: 5 | B17: =IF(5>Reglages!$G$13,"",$B$4*(1-Reglages!$I$13*4)) | C17: =IF(5>Reglages!$G$13,"",$B$5*Reglages!$H$13^4/SUMPRODUCT(Reglages!$H$13^(ROW(INDIRECT("1:"&Reglages!$G$13))-1))) | G17: =IF(OR(D17<>1,E17="",E17=0),0,F17/E17*(1-Reglages!$B$5)) | H17: =SUM($F$13:F17) | I17: =SUM($G$13:G17) | J17: =IF(I17=0,"",H17/I17) | K17: =IF(I17=0,"",J17*(1+$B$8)/(1-Reglages!$B$5)) | L17: =I17*$B$9 | M17: =IF(I17=0,"",L17-H17) | N17: =IF(OR(I17=0,B17=""),"",K17/B17-1)
A18: 6 | B18: =IF(6>Reglages!$G$13,"",$B$4*(1-Reglages!$I$13*5)) | C18: =IF(6>Reglages!$G$13,"",$B$5*Reglages!$H$13^5/SUMPRODUCT(Reglages!$H$13^(ROW(INDIRECT("1:"&Reglages!$G$13))-1))) | G18: =IF(OR(D18<>1,E18="",E18=0),0,F18/E18*(1-Reglages!$B$5)) | H18: =SUM($F$13:F18) | I18: =SUM($G$13:G18) | J18: =IF(I18=0,"",H18/I18) | K18: =IF(I18=0,"",J18*(1+$B$8)/(1-Reglages!$B$5)) | L18: =I18*$B$9 | M18: =IF(I18=0,"",L18-H18) | N18: =IF(OR(I18=0,B18=""),"",K18/B18-1)
A19: 7 | B19: =IF(7>Reglages!$G$13,"",$B$4*(1-Reglages!$I$13*6)) | C19: =IF(7>Reglages!$G$13,"",$B$5*Reglages!$H$13^6/SUMPRODUCT(Reglages!$H$13^(ROW(INDIRECT("1:"&Reglages!$G$13))-1))) | G19: =IF(OR(D19<>1,E19="",E19=0),0,F19/E19*(1-Reglages!$B$5)) | H19: =SUM($F$13:F19) | I19: =SUM($G$13:G19) | J19: =IF(I19=0,"",H19/I19) | K19: =IF(I19=0,"",J19*(1+$B$8)/(1-Reglages!$B$5)) | L19: =I19*$B$9 | M19: =IF(I19=0,"",L19-H19) | N19: =IF(OR(I19=0,B19=""),"",K19/B19-1)
A20: 8 | B20: =IF(8>Reglages!$G$13,"",$B$4*(1-Reglages!$I$13*7)) | C20: =IF(8>Reglages!$G$13,"",$B$5*Reglages!$H$13^7/SUMPRODUCT(Reglages!$H$13^(ROW(INDIRECT("1:"&Reglages!$G$13))-1))) | G20: =IF(OR(D20<>1,E20="",E20=0),0,F20/E20*(1-Reglages!$B$5)) | H20: =SUM($F$13:F20) | I20: =SUM($G$13:G20) | J20: =IF(I20=0,"",H20/I20) | K20: =IF(I20=0,"",J20*(1+$B$8)/(1-Reglages!$B$5)) | L20: =I20*$B$9 | M20: =IF(I20=0,"",L20-H20) | N20: =IF(OR(I20=0,B20=""),"",K20/B20-1)
A21: 9 | B21: =IF(9>Reglages!$G$13,"",$B$4*(1-Reglages!$I$13*8)) | C21: =IF(9>Reglages!$G$13,"",$B$5*Reglages!$H$13^8/SUMPRODUCT(Reglages!$H$13^(ROW(INDIRECT("1:"&Reglages!$G$13))-1))) | G21: =IF(OR(D21<>1,E21="",E21=0),0,F21/E21*(1-Reglages!$B$5)) | H21: =SUM($F$13:F21) | I21: =SUM($G$13:G21) | J21: =IF(I21=0,"",H21/I21) | K21: =IF(I21=0,"",J21*(1+$B$8)/(1-Reglages!$B$5)) | L21: =I21*$B$9 | M21: =IF(I21=0,"",L21-H21) | N21: =IF(OR(I21=0,B21=""),"",K21/B21-1)
A22: 10 | B22: =IF(10>Reglages!$G$13,"",$B$4*(1-Reglages!$I$13*9)) | C22: =IF(10>Reglages!$G$13,"",$B$5*Reglages!$H$13^9/SUMPRODUCT(Reglages!$H$13^(ROW(INDIRECT("1:"&Reglages!$G$13))-1))) | G22: =IF(OR(D22<>1,E22="",E22=0),0,F22/E22*(1-Reglages!$B$5)) | H22: =SUM($F$13:F22) | I22: =SUM($G$13:G22) | J22: =IF(I22=0,"",H22/I22) | K22: =IF(I22=0,"",J22*(1+$B$8)/(1-Reglages!$B$5)) | L22: =I22*$B$9 | M22: =IF(I22=0,"",L22-H22) | N22: =IF(OR(I22=0,B22=""),"",K22/B22-1)
A23: 11 | B23: =IF(11>Reglages!$G$13,"",$B$4*(1-Reglages!$I$13*10)) | C23: =IF(11>Reglages!$G$13,"",$B$5*Reglages!$H$13^10/SUMPRODUCT(Reglages!$H$13^(ROW(INDIRECT("1:"&Reglages!$G$13))-1))) | G23: =IF(OR(D23<>1,E23="",E23=0),0,F23/E23*(1-Reglages!$B$5)) | H23: =SUM($F$13:F23) | I23: =SUM($G$13:G23) | J23: =IF(I23=0,"",H23/I23) | K23: =IF(I23=0,"",J23*(1+$B$8)/(1-Reglages!$B$5)) | L23: =I23*$B$9 | M23: =IF(I23=0,"",L23-H23) | N23: =IF(OR(I23=0,B23=""),"",K23/B23-1)
A24: 12 | B24: =IF(12>Reglages!$G$13,"",$B$4*(1-Reglages!$I$13*11)) | C24: =IF(12>Reglages!$G$13,"",$B$5*Reglages!$H$13^11/SUMPRODUCT(Reglages!$H$13^(ROW(INDIRECT("1:"&Reglages!$G$13))-1))) | G24: =IF(OR(D24<>1,E24="",E24=0),0,F24/E24*(1-Reglages!$B$5)) | H24: =SUM($F$13:F24) | I24: =SUM($G$13:G24) | J24: =IF(I24=0,"",H24/I24) | K24: =IF(I24=0,"",J24*(1+$B$8)/(1-Reglages!$B$5)) | L24: =I24*$B$9 | M24: =IF(I24=0,"",L24-H24) | N24: =IF(OR(I24=0,B24=""),"",K24/B24-1)
A25: 13 | B25: =IF(13>Reglages!$G$13,"",$B$4*(1-Reglages!$I$13*12)) | C25: =IF(13>Reglages!$G$13,"",$B$5*Reglages!$H$13^12/SUMPRODUCT(Reglages!$H$13^(ROW(INDIRECT("1:"&Reglages!$G$13))-1))) | G25: =IF(OR(D25<>1,E25="",E25=0),0,F25/E25*(1-Reglages!$B$5)) | H25: =SUM($F$13:F25) | I25: =SUM($G$13:G25) | J25: =IF(I25=0,"",H25/I25) | K25: =IF(I25=0,"",J25*(1+$B$8)/(1-Reglages!$B$5)) | L25: =I25*$B$9 | M25: =IF(I25=0,"",L25-H25) | N25: =IF(OR(I25=0,B25=""),"",K25/B25-1)
A26: 14 | B26: =IF(14>Reglages!$G$13,"",$B$4*(1-Reglages!$I$13*13)) | C26: =IF(14>Reglages!$G$13,"",$B$5*Reglages!$H$13^13/SUMPRODUCT(Reglages!$H$13^(ROW(INDIRECT("1:"&Reglages!$G$13))-1))) | G26: =IF(OR(D26<>1,E26="",E26=0),0,F26/E26*(1-Reglages!$B$5)) | H26: =SUM($F$13:F26) | I26: =SUM($G$13:G26) | J26: =IF(I26=0,"",H26/I26) | K26: =IF(I26=0,"",J26*(1+$B$8)/(1-Reglages!$B$5)) | L26: =I26*$B$9 | M26: =IF(I26=0,"",L26-H26) | N26: =IF(OR(I26=0,B26=""),"",K26/B26-1)
A27: TOTAL | C27: =SUM(C13:C26) | F27: =SUM(F13:F26) | G27: =SUM(G13:G26) | J27: =IF(G27=0,"",F27/G27) | K27: =IF(G27=0,"",J27*(1+$B$8)/(1-Reglages!$B$5)) | L27: =G27*$B$9 | M27: =IF(G27=0,"",L27-F27) | N27: =IF(OR(G27=0,$B$9=0),"",K27/$B$9-1)
A29: Si vous revendez tout maintenant au prix de revente | E29: =IF(G27=0,"",F27*$B$8)
A30: Etat de la descente | E30: =IF(G27=0,"pas commencee",IF($B$9<=$E$6,"ABANDON : sous le seuil",IF(AND($E$5<>"",$E$5>Reglages!$B$8),"BLOQUEE : trop longue",IF($B$9>=K27,"REVENDRE MAINTENANT",IF(COUNT(D13:D26)-COUNTIF(D13:D26,1)=0,"echelle epuisee","en cours"))))

Sheet ADA
A1: Descente ADA
A2: Colonnes jaunes : a remplir quand l'achat est passe. Le reste est calcule.
A4: Prix de reference | B4: =Reglages!B14 | D4: Date du premier achat
A5: Budget alloue | B5: =Reglages!E14 | D5: Jours ecoules | E5: =IF(E4="","",TODAY()-E4)
A6: Profondeur de l'echelle | B6: =Reglages!F14 | D6: Seuil d'abandon | E6: =B7*(1-0.15) | F6: 15 % sous le dernier palier. En dessous, on n'ajoute plus rien.
A7: Prix du dernier palier | B7: =Reglages!J14
A8: Objectif net a la revente | B8: =Reglages!B6
A9: Prix actuel du marche | B9: 0.2173
A12: Palier | B12: Prix cible | C12: Mise prevue (EUR) | D12: Fait ? (1 = oui) | E12: Prix reellement paye | F12: Montant reellement investi (EUR) | G12: Unites obtenues | H12: Cumul investi | I12: Cumul unites | J12: Prix de revient moyen | K12: Prix de revente (+2 % net) | L12: Valeur au prix actuel | M12: P&L latent | N12: Rebond requis depuis ce palier
A13: 1 | B13: =IF(1>Reglages!$G$14,"",$B$4*(1-Reglages!$I$14*0)) | C13: =IF(1>Reglages!$G$14,"",$B$5*Reglages!$H$14^0/SUMPRODUCT(Reglages!$H$14^(ROW(INDIRECT("1:"&Reglages!$G$14))-1))) | G13: =IF(OR(D13<>1,E13="",E13=0),0,F13/E13*(1-Reglages!$B$5)) | H13: =SUM($F$13:F13) | I13: =SUM($G$13:G13) | J13: =IF(I13=0,"",H13/I13) | K13: =IF(I13=0,"",J13*(1+$B$8)/(1-Reglages!$B$5)) | L13: =I13*$B$9 | M13: =IF(I13=0,"",L13-H13) | N13: =IF(OR(I13=0,B13=""),"",K13/B13-1)
A14: 2 | B14: =IF(2>Reglages!$G$14,"",$B$4*(1-Reglages!$I$14*1)) | C14: =IF(2>Reglages!$G$14,"",$B$5*Reglages!$H$14^1/SUMPRODUCT(Reglages!$H$14^(ROW(INDIRECT("1:"&Reglages!$G$14))-1))) | G14: =IF(OR(D14<>1,E14="",E14=0),0,F14/E14*(1-Reglages!$B$5)) | H14: =SUM($F$13:F14) | I14: =SUM($G$13:G14) | J14: =IF(I14=0,"",H14/I14) | K14: =IF(I14=0,"",J14*(1+$B$8)/(1-Reglages!$B$5)) | L14: =I14*$B$9 | M14: =IF(I14=0,"",L14-H14) | N14: =IF(OR(I14=0,B14=""),"",K14/B14-1)
A15: 3 | B15: =IF(3>Reglages!$G$14,"",$B$4*(1-Reglages!$I$14*2)) | C15: =IF(3>Reglages!$G$14,"",$B$5*Reglages!$H$14^2/SUMPRODUCT(Reglages!$H$14^(ROW(INDIRECT("1:"&Reglages!$G$14))-1))) | G15: =IF(OR(D15<>1,E15="",E15=0),0,F15/E15*(1-Reglages!$B$5)) | H15: =SUM($F$13:F15) | I15: =SUM($G$13:G15) | J15: =IF(I15=0,"",H15/I15) | K15: =IF(I15=0,"",J15*(1+$B$8)/(1-Reglages!$B$5)) | L15: =I15*$B$9 | M15: =IF(I15=0,"",L15-H15) | N15: =IF(OR(I15=0,B15=""),"",K15/B15-1)
A16: 4 | B16: =IF(4>Reglages!$G$14,"",$B$4*(1-Reglages!$I$14*3)) | C16: =IF(4>Reglages!$G$14,"",$B$5*Reglages!$H$14^3/SUMPRODUCT(Reglages!$H$14^(ROW(INDIRECT("1:"&Reglages!$G$14))-1))) | G16: =IF(OR(D16<>1,E16="",E16=0),0,F16/E16*(1-Reglages!$B$5)) | H16: =SUM($F$13:F16) | I16: =SUM($G$13:G16) | J16: =IF(I16=0,"",H16/I16) | K16: =IF(I16=0,"",J16*(1+$B$8)/(1-Reglages!$B$5)) | L16: =I16*$B$9 | M16: =IF(I16=0,"",L16-H16) | N16: =IF(OR(I16=0,B16=""),"",K16/B16-1)
A17: 5 | B17: =IF(5>Reglages!$G$14,"",$B$4*(1-Reglages!$I$14*4)) | C17: =IF(5>Reglages!$G$14,"",$B$5*Reglages!$H$14^4/SUMPRODUCT(Reglages!$H$14^(ROW(INDIRECT("1:"&Reglages!$G$14))-1))) | G17: =IF(OR(D17<>1,E17="",E17=0),0,F17/E17*(1-Reglages!$B$5)) | H17: =SUM($F$13:F17) | I17: =SUM($G$13:G17) | J17: =IF(I17=0,"",H17/I17) | K17: =IF(I17=0,"",J17*(1+$B$8)/(1-Reglages!$B$5)) | L17: =I17*$B$9 | M17: =IF(I17=0,"",L17-H17) | N17: =IF(OR(I17=0,B17=""),"",K17/B17-1)
A18: 6 | B18: =IF(6>Reglages!$G$14,"",$B$4*(1-Reglages!$I$14*5)) | C18: =IF(6>Reglages!$G$14,"",$B$5*Reglages!$H$14^5/SUMPRODUCT(Reglages!$H$14^(ROW(INDIRECT("1:"&Reglages!$G$14))-1))) | G18: =IF(OR(D18<>1,E18="",E18=0),0,F18/E18*(1-Reglages!$B$5)) | H18: =SUM($F$13:F18) | I18: =SUM($G$13:G18) | J18: =IF(I18=0,"",H18/I18) | K18: =IF(I18=0,"",J18*(1+$B$8)/(1-Reglages!$B$5)) | L18: =I18*$B$9 | M18: =IF(I18=0,"",L18-H18) | N18: =IF(OR(I18=0,B18=""),"",K18/B18-1)
A19: 7 | B19: =IF(7>Reglages!$G$14,"",$B$4*(1-Reglages!$I$14*6)) | C19: =IF(7>Reglages!$G$14,"",$B$5*Reglages!$H$14^6/SUMPRODUCT(Reglages!$H$14^(ROW(INDIRECT("1:"&Reglages!$G$14))-1))) | G19: =IF(OR(D19<>1,E19="",E19=0),0,F19/E19*(1-Reglages!$B$5)) | H19: =SUM($F$13:F19) | I19: =SUM($G$13:G19) | J19: =IF(I19=0,"",H19/I19) | K19: =IF(I19=0,"",J19*(1+$B$8)/(1-Reglages!$B$5)) | L19: =I19*$B$9 | M19: =IF(I19=0,"",L19-H19) | N19: =IF(OR(I19=0,B19=""),"",K19/B19-1)
A20: 8 | B20: =IF(8>Reglages!$G$14,"",$B$4*(1-Reglages!$I$14*7)) | C20: =IF(8>Reglages!$G$14,"",$B$5*Reglages!$H$14^7/SUMPRODUCT(Reglages!$H$14^(ROW(INDIRECT("1:"&Reglages!$G$14))-1))) | G20: =IF(OR(D20<>1,E20="",E20=0),0,F20/E20*(1-Reglages!$B$5)) | H20: =SUM($F$13:F20) | I20: =SUM($G$13:G20) | J20: =IF(I20=0,"",H20/I20) | K20: =IF(I20=0,"",J20*(1+$B$8)/(1-Reglages!$B$5)) | L20: =I20*$B$9 | M20: =IF(I20=0,"",L20-H20) | N20: =IF(OR(I20=0,B20=""),"",K20/B20-1)
A21: 9 | B21: =IF(9>Reglages!$G$14,"",$B$4*(1-Reglages!$I$14*8)) | C21: =IF(9>Reglages!$G$14,"",$B$5*Reglages!$H$14^8/SUMPRODUCT(Reglages!$H$14^(ROW(INDIRECT("1:"&Reglages!$G$14))-1))) | G21: =IF(OR(D21<>1,E21="",E21=0),0,F21/E21*(1-Reglages!$B$5)) | H21: =SUM($F$13:F21) | I21: =SUM($G$13:G21) | J21: =IF(I21=0,"",H21/I21) | K21: =IF(I21=0,"",J21*(1+$B$8)/(1-Reglages!$B$5)) | L21: =I21*$B$9 | M21: =IF(I21=0,"",L21-H21) | N21: =IF(OR(I21=0,B21=""),"",K21/B21-1)
A22: 10 | B22: =IF(10>Reglages!$G$14,"",$B$4*(1-Reglages!$I$14*9)) | C22: =IF(10>Reglages!$G$14,"",$B$5*Reglages!$H$14^9/SUMPRODUCT(Reglages!$H$14^(ROW(INDIRECT("1:"&Reglages!$G$14))-1))) | G22: =IF(OR(D22<>1,E22="",E22=0),0,F22/E22*(1-Reglages!$B$5)) | H22: =SUM($F$13:F22) | I22: =SUM($G$13:G22) | J22: =IF(I22=0,"",H22/I22) | K22: =IF(I22=0,"",J22*(1+$B$8)/(1-Reglages!$B$5)) | L22: =I22*$B$9 | M22: =IF(I22=0,"",L22-H22) | N22: =IF(OR(I22=0,B22=""),"",K22/B22-1)
A23: 11 | B23: =IF(11>Reglages!$G$14,"",$B$4*(1-Reglages!$I$14*10)) | C23: =IF(11>Reglages!$G$14,"",$B$5*Reglages!$H$14^10/SUMPRODUCT(Reglages!$H$14^(ROW(INDIRECT("1:"&Reglages!$G$14))-1))) | G23: =IF(OR(D23<>1,E23="",E23=0),0,F23/E23*(1-Reglages!$B$5)) | H23: =SUM($F$13:F23) | I23: =SUM($G$13:G23) | J23: =IF(I23=0,"",H23/I23) | K23: =IF(I23=0,"",J23*(1+$B$8)/(1-Reglages!$B$5)) | L23: =I23*$B$9 | M23: =IF(I23=0,"",L23-H23) | N23: =IF(OR(I23=0,B23=""),"",K23/B23-1)
A24: 12 | B24: =IF(12>Reglages!$G$14,"",$B$4*(1-Reglages!$I$14*11)) | C24: =IF(12>Reglages!$G$14,"",$B$5*Reglages!$H$14^11/SUMPRODUCT(Reglages!$H$14^(ROW(INDIRECT("1:"&Reglages!$G$14))-1))) | G24: =IF(OR(D24<>1,E24="",E24=0),0,F24/E24*(1-Reglages!$B$5)) | H24: =SUM($F$13:F24) | I24: =SUM($G$13:G24) | J24: =IF(I24=0,"",H24/I24) | K24: =IF(I24=0,"",J24*(1+$B$8)/(1-Reglages!$B$5)) | L24: =I24*$B$9 | M24: =IF(I24=0,"",L24-H24) | N24: =IF(OR(I24=0,B24=""),"",K24/B24-1)
A25: 13 | B25: =IF(13>Reglages!$G$14,"",$B$4*(1-Reglages!$I$14*12)) | C25: =IF(13>Reglages!$G$14,"",$B$5*Reglages!$H$14^12/SUMPRODUCT(Reglages!$H$14^(ROW(INDIRECT("1:"&Reglages!$G$14))-1))) | G25: =IF(OR(D25<>1,E25="",E25=0),0,F25/E25*(1-Reglages!$B$5)) | H25: =SUM($F$13:F25) | I25: =SUM($G$13:G25) | J25: =IF(I25=0,"",H25/I25) | K25: =IF(I25=0,"",J25*(1+$B$8)/(1-Reglages!$B$5)) | L25: =I25*$B$9 | M25: =IF(I25=0,"",L25-H25) | N25: =IF(OR(I25=0,B25=""),"",K25/B25-1)
A26: 14 | B26: =IF(14>Reglages!$G$14,"",$B$4*(1-Reglages!$I$14*13)) | C26: =IF(14>Reglages!$G$14,"",$B$5*Reglages!$H$14^13/SUMPRODUCT(Reglages!$H$14^(ROW(INDIRECT("1:"&Reglages!$G$14))-1))) | G26: =IF(OR(D26<>1,E26="",E26=0),0,F26/E26*(1-Reglages!$B$5)) | H26: =SUM($F$13:F26) | I26: =SUM($G$13:G26) | J26: =IF(I26=0,"",H26/I26) | K26: =IF(I26=0,"",J26*(1+$B$8)/(1-Reglages!$B$5)) | L26: =I26*$B$9 | M26: =IF(I26=0,"",L26-H26) | N26: =IF(OR(I26=0,B26=""),"",K26/B26-1)
A27: TOTAL | C27: =SUM(C13:C26) | F27: =SUM(F13:F26) | G27: =SUM(G13:G26) | J27: =IF(G27=0,"",F27/G27) | K27: =IF(G27=0,"",J27*(1+$B$8)/(1-Reglages!$B$5)) | L27: =G27*$B$9 | M27: =IF(G27=0,"",L27-F27) | N27: =IF(OR(G27=0,$B$9=0),"",K27/$B$9-1)
A29: Si vous revendez tout maintenant au prix de revente | E29: =IF(G27=0,"",F27*$B$8)
A30: Etat de la descente | E30: =IF(G27=0,"pas commencee",IF($B$9<=$E$6,"ABANDON : sous le seuil",IF(AND($E$5<>"",$E$5>Reglages!$B$8),"BLOQUEE : trop longue",IF($B$9>=K27,"REVENDRE MAINTENANT",IF(COUNT(D13:D26)-COUNTIF(D13:D26,1)=0,"echelle epuisee","en cours"))))

Sheet BCH
A1: Descente BCH
A2: Colonnes jaunes : a remplir quand l'achat est passe. Le reste est calcule.
A4: Prix de reference | B4: =Reglages!B15 | D4: Date du premier achat
A5: Budget alloue | B5: =Reglages!E15 | D5: Jours ecoules | E5: =IF(E4="","",TODAY()-E4)
A6: Profondeur de l'echelle | B6: =Reglages!F15 | D6: Seuil d'abandon | E6: =B7*(1-0.15) | F6: 15 % sous le dernier palier. En dessous, on n'ajoute plus rien.
A7: Prix du dernier palier | B7: =Reglages!J15
A8: Objectif net a la revente | B8: =Reglages!B6
A9: Prix actuel du marche | B9: 256.6
A12: Palier | B12: Prix cible | C12: Mise prevue (EUR) | D12: Fait ? (1 = oui) | E12: Prix reellement paye | F12: Montant reellement investi (EUR) | G12: Unites obtenues | H12: Cumul investi | I12: Cumul unites | J12: Prix de revient moyen | K12: Prix de revente (+2 % net) | L12: Valeur au prix actuel | M12: P&L latent | N12: Rebond requis depuis ce palier
A13: 1 | B13: =IF(1>Reglages!$G$15,"",$B$4*(1-Reglages!$I$15*0)) | C13: =IF(1>Reglages!$G$15,"",$B$5*Reglages!$H$15^0/SUMPRODUCT(Reglages!$H$15^(ROW(INDIRECT("1:"&Reglages!$G$15))-1))) | G13: =IF(OR(D13<>1,E13="",E13=0),0,F13/E13*(1-Reglages!$B$5)) | H13: =SUM($F$13:F13) | I13: =SUM($G$13:G13) | J13: =IF(I13=0,"",H13/I13) | K13: =IF(I13=0,"",J13*(1+$B$8)/(1-Reglages!$B$5)) | L13: =I13*$B$9 | M13: =IF(I13=0,"",L13-H13) | N13: =IF(OR(I13=0,B13=""),"",K13/B13-1)
A14: 2 | B14: =IF(2>Reglages!$G$15,"",$B$4*(1-Reglages!$I$15*1)) | C14: =IF(2>Reglages!$G$15,"",$B$5*Reglages!$H$15^1/SUMPRODUCT(Reglages!$H$15^(ROW(INDIRECT("1:"&Reglages!$G$15))-1))) | G14: =IF(OR(D14<>1,E14="",E14=0),0,F14/E14*(1-Reglages!$B$5)) | H14: =SUM($F$13:F14) | I14: =SUM($G$13:G14) | J14: =IF(I14=0,"",H14/I14) | K14: =IF(I14=0,"",J14*(1+$B$8)/(1-Reglages!$B$5)) | L14: =I14*$B$9 | M14: =IF(I14=0,"",L14-H14) | N14: =IF(OR(I14=0,B14=""),"",K14/B14-1)
A15: 3 | B15: =IF(3>Reglages!$G$15,"",$B$4*(1-Reglages!$I$15*2)) | C15: =IF(3>Reglages!$G$15,"",$B$5*Reglages!$H$15^2/SUMPRODUCT(Reglages!$H$15^(ROW(INDIRECT("1:"&Reglages!$G$15))-1))) | G15: =IF(OR(D15<>1,E15="",E15=0),0,F15/E15*(1-Reglages!$B$5)) | H15: =SUM($F$13:F15) | I15: =SUM($G$13:G15) | J15: =IF(I15=0,"",H15/I15) | K15: =IF(I15=0,"",J15*(1+$B$8)/(1-Reglages!$B$5)) | L15: =I15*$B$9 | M15: =IF(I15=0,"",L15-H15) | N15: =IF(OR(I15=0,B15=""),"",K15/B15-1)
A16: 4 | B16: =IF(4>Reglages!$G$15,"",$B$4*(1-Reglages!$I$15*3)) | C16: =IF(4>Reglages!$G$15,"",$B$5*Reglages!$H$15^3/SUMPRODUCT(Reglages!$H$15^(ROW(INDIRECT("1:"&Reglages!$G$15))-1))) | G16: =IF(OR(D16<>1,E16="",E16=0),0,F16/E16*(1-Reglages!$B$5)) | H16: =SUM($F$13:F16) | I16: =SUM($G$13:G16) | J16: =IF(I16=0,"",H16/I16) | K16: =IF(I16=0,"",J16*(1+$B$8)/(1-Reglages!$B$5)) | L16: =I16*$B$9 | M16: =IF(I16=0,"",L16-H16) | N16: =IF(OR(I16=0,B16=""),"",K16/B16-1)
A17: 5 | B17: =IF(5>Reglages!$G$15,"",$B$4*(1-Reglages!$I$15*4)) | C17: =IF(5>Reglages!$G$15,"",$B$5*Reglages!$H$15^4/SUMPRODUCT(Reglages!$H$15^(ROW(INDIRECT("1:"&Reglages!$G$15))-1))) | G17: =IF(OR(D17<>1,E17="",E17=0),0,F17/E17*(1-Reglages!$B$5)) | H17: =SUM($F$13:F17) | I17: =SUM($G$13:G17) | J17: =IF(I17=0,"",H17/I17) | K17: =IF(I17=0,"",J17*(1+$B$8)/(1-Reglages!$B$5)) | L17: =I17*$B$9 | M17: =IF(I17=0,"",L17-H17) | N17: =IF(OR(I17=0,B17=""),"",K17/B17-1)
A18: 6 | B18: =IF(6>Reglages!$G$15,"",$B$4*(1-Reglages!$I$15*5)) | C18: =IF(6>Reglages!$G$15,"",$B$5*Reglages!$H$15^5/SUMPRODUCT(Reglages!$H$15^(ROW(INDIRECT("1:"&Reglages!$G$15))-1))) | G18: =IF(OR(D18<>1,E18="",E18=0),0,F18/E18*(1-Reglages!$B$5)) | H18: =SUM($F$13:F18) | I18: =SUM($G$13:G18) | J18: =IF(I18=0,"",H18/I18) | K18: =IF(I18=0,"",J18*(1+$B$8)/(1-Reglages!$B$5)) | L18: =I18*$B$9 | M18: =IF(I18=0,"",L18-H18) | N18: =IF(OR(I18=0,B18=""),"",K18/B18-1)
A19: 7 | B19: =IF(7>Reglages!$G$15,"",$B$4*(1-Reglages!$I$15*6)) | C19: =IF(7>Reglages!$G$15,"",$B$5*Reglages!$H$15^6/SUMPRODUCT(Reglages!$H$15^(ROW(INDIRECT("1:"&Reglages!$G$15))-1))) | G19: =IF(OR(D19<>1,E19="",E19=0),0,F19/E19*(1-Reglages!$B$5)) | H19: =SUM($F$13:F19) | I19: =SUM($G$13:G19) | J19: =IF(I19=0,"",H19/I19) | K19: =IF(I19=0,"",J19*(1+$B$8)/(1-Reglages!$B$5)) | L19: =I19*$B$9 | M19: =IF(I19=0,"",L19-H19) | N19: =IF(OR(I19=0,B19=""),"",K19/B19-1)
A20: 8 | B20: =IF(8>Reglages!$G$15,"",$B$4*(1-Reglages!$I$15*7)) | C20: =IF(8>Reglages!$G$15,"",$B$5*Reglages!$H$15^7/SUMPRODUCT(Reglages!$H$15^(ROW(INDIRECT("1:"&Reglages!$G$15))-1))) | G20: =IF(OR(D20<>1,E20="",E20=0),0,F20/E20*(1-Reglages!$B$5)) | H20: =SUM($F$13:F20) | I20: =SUM($G$13:G20) | J20: =IF(I20=0,"",H20/I20) | K20: =IF(I20=0,"",J20*(1+$B$8)/(1-Reglages!$B$5)) | L20: =I20*$B$9 | M20: =IF(I20=0,"",L20-H20) | N20: =IF(OR(I20=0,B20=""),"",K20/B20-1)
A21: 9 | B21: =IF(9>Reglages!$G$15,"",$B$4*(1-Reglages!$I$15*8)) | C21: =IF(9>Reglages!$G$15,"",$B$5*Reglages!$H$15^8/SUMPRODUCT(Reglages!$H$15^(ROW(INDIRECT("1:"&Reglages!$G$15))-1))) | G21: =IF(OR(D21<>1,E21="",E21=0),0,F21/E21*(1-Reglages!$B$5)) | H21: =SUM($F$13:F21) | I21: =SUM($G$13:G21) | J21: =IF(I21=0,"",H21/I21) | K21: =IF(I21=0,"",J21*(1+$B$8)/(1-Reglages!$B$5)) | L21: =I21*$B$9 | M21: =IF(I21=0,"",L21-H21) | N21: =IF(OR(I21=0,B21=""),"",K21/B21-1)
A22: 10 | B22: =IF(10>Reglages!$G$15,"",$B$4*(1-Reglages!$I$15*9)) | C22: =IF(10>Reglages!$G$15,"",$B$5*Reglages!$H$15^9/SUMPRODUCT(Reglages!$H$15^(ROW(INDIRECT("1:"&Reglages!$G$15))-1))) | G22: =IF(OR(D22<>1,E22="",E22=0),0,F22/E22*(1-Reglages!$B$5)) | H22: =SUM($F$13:F22) | I22: =SUM($G$13:G22) | J22: =IF(I22=0,"",H22/I22) | K22: =IF(I22=0,"",J22*(1+$B$8)/(1-Reglages!$B$5)) | L22: =I22*$B$9 | M22: =IF(I22=0,"",L22-H22) | N22: =IF(OR(I22=0,B22=""),"",K22/B22-1)
A23: 11 | B23: =IF(11>Reglages!$G$15,"",$B$4*(1-Reglages!$I$15*10)) | C23: =IF(11>Reglages!$G$15,"",$B$5*Reglages!$H$15^10/SUMPRODUCT(Reglages!$H$15^(ROW(INDIRECT("1:"&Reglages!$G$15))-1))) | G23: =IF(OR(D23<>1,E23="",E23=0),0,F23/E23*(1-Reglages!$B$5)) | H23: =SUM($F$13:F23) | I23: =SUM($G$13:G23) | J23: =IF(I23=0,"",H23/I23) | K23: =IF(I23=0,"",J23*(1+$B$8)/(1-Reglages!$B$5)) | L23: =I23*$B$9 | M23: =IF(I23=0,"",L23-H23) | N23: =IF(OR(I23=0,B23=""),"",K23/B23-1)
A24: 12 | B24: =IF(12>Reglages!$G$15,"",$B$4*(1-Reglages!$I$15*11)) | C24: =IF(12>Reglages!$G$15,"",$B$5*Reglages!$H$15^11/SUMPRODUCT(Reglages!$H$15^(ROW(INDIRECT("1:"&Reglages!$G$15))-1))) | G24: =IF(OR(D24<>1,E24="",E24=0),0,F24/E24*(1-Reglages!$B$5)) | H24: =SUM($F$13:F24) | I24: =SUM($G$13:G24) | J24: =IF(I24=0,"",H24/I24) | K24: =IF(I24=0,"",J24*(1+$B$8)/(1-Reglages!$B$5)) | L24: =I24*$B$9 | M24: =IF(I24=0,"",L24-H24) | N24: =IF(OR(I24=0,B24=""),"",K24/B24-1)
A25: 13 | B25: =IF(13>Reglages!$G$15,"",$B$4*(1-Reglages!$I$15*12)) | C25: =IF(13>Reglages!$G$15,"",$B$5*Reglages!$H$15^12/SUMPRODUCT(Reglages!$H$15^(ROW(INDIRECT("1:"&Reglages!$G$15))-1))) | G25: =IF(OR(D25<>1,E25="",E25=0),0,F25/E25*(1-Reglages!$B$5)) | H25: =SUM($F$13:F25) | I25: =SUM($G$13:G25) | J25: =IF(I25=0,"",H25/I25) | K25: =IF(I25=0,"",J25*(1+$B$8)/(1-Reglages!$B$5)) | L25: =I25*$B$9 | M25: =IF(I25=0,"",L25-H25) | N25: =IF(OR(I25=0,B25=""),"",K25/B25-1)
A26: 14 | B26: =IF(14>Reglages!$G$15,"",$B$4*(1-Reglages!$I$15*13)) | C26: =IF(14>Reglages!$G$15,"",$B$5*Reglages!$H$15^13/SUMPRODUCT(Reglages!$H$15^(ROW(INDIRECT("1:"&Reglages!$G$15))-1))) | G26: =IF(OR(D26<>1,E26="",E26=0),0,F26/E26*(1-Reglages!$B$5)) | H26: =SUM($F$13:F26) | I26: =SUM($G$13:G26) | J26: =IF(I26=0,"",H26/I26) | K26: =IF(I26=0,"",J26*(1+$B$8)/(1-Reglages!$B$5)) | L26: =I26*$B$9 | M26: =IF(I26=0,"",L26-H26) | N26: =IF(OR(I26=0,B26=""),"",K26/B26-1)
A27: TOTAL | C27: =SUM(C13:C26) | F27: =SUM(F13:F26) | G27: =SUM(G13:G26) | J27: =IF(G27=0,"",F27/G27) | K27: =IF(G27=0,"",J27*(1+$B$8)/(1-Reglages!$B$5)) | L27: =G27*$B$9 | M27: =IF(G27=0,"",L27-F27) | N27: =IF(OR(G27=0,$B$9=0),"",K27/$B$9-1)
A29: Si vous revendez tout maintenant au prix de revente | E29: =IF(G27=0,"",F27*$B$8)
A30: Etat de la descente | E30: =IF(G27=0,"pas commencee",IF($B$9<=$E$6,"ABANDON : sous le seuil",IF(AND($E$5<>"",$E$5>Reglages!$B$8),"BLOQUEE : trop longue",IF($B$9>=K27,"REVENDRE MAINTENANT",IF(COUNT(D13:D26)-COUNTIF(D13:D26,1)=0,"echelle epuisee","en cours"))))

Sheet DGB
A1: Descente DGB
A2: Colonnes jaunes : a remplir quand l'achat est passe. Le reste est calcule.
A4: Prix de reference | B4: =Reglages!B16 | D4: Date du premier achat
A5: Budget alloue | B5: =Reglages!E16 | D5: Jours ecoules | E5: =IF(E4="","",TODAY()-E4)
A6: Profondeur de l'echelle | B6: =Reglages!F16 | D6: Seuil d'abandon | E6: =B7*(1-0.15) | F6: 15 % sous le dernier palier. En dessous, on n'ajoute plus rien.
A7: Prix du dernier palier | B7: =Reglages!J16
A8: Objectif net a la revente | B8: =Reglages!B6
A9: Prix actuel du marche | B9: 0.00507
A12: Palier | B12: Prix cible | C12: Mise prevue (EUR) | D12: Fait ? (1 = oui) | E12: Prix reellement paye | F12: Montant reellement investi (EUR) | G12: Unites obtenues | H12: Cumul investi | I12: Cumul unites | J12: Prix de revient moyen | K12: Prix de revente (+2 % net) | L12: Valeur au prix actuel | M12: P&L latent | N12: Rebond requis depuis ce palier
A13: 1 | B13: =IF(1>Reglages!$G$16,"",$B$4*(1-Reglages!$I$16*0)) | C13: =IF(1>Reglages!$G$16,"",$B$5*Reglages!$H$16^0/SUMPRODUCT(Reglages!$H$16^(ROW(INDIRECT("1:"&Reglages!$G$16))-1))) | G13: =IF(OR(D13<>1,E13="",E13=0),0,F13/E13*(1-Reglages!$B$5)) | H13: =SUM($F$13:F13) | I13: =SUM($G$13:G13) | J13: =IF(I13=0,"",H13/I13) | K13: =IF(I13=0,"",J13*(1+$B$8)/(1-Reglages!$B$5)) | L13: =I13*$B$9 | M13: =IF(I13=0,"",L13-H13) | N13: =IF(OR(I13=0,B13=""),"",K13/B13-1)
A14: 2 | B14: =IF(2>Reglages!$G$16,"",$B$4*(1-Reglages!$I$16*1)) | C14: =IF(2>Reglages!$G$16,"",$B$5*Reglages!$H$16^1/SUMPRODUCT(Reglages!$H$16^(ROW(INDIRECT("1:"&Reglages!$G$16))-1))) | G14: =IF(OR(D14<>1,E14="",E14=0),0,F14/E14*(1-Reglages!$B$5)) | H14: =SUM($F$13:F14) | I14: =SUM($G$13:G14) | J14: =IF(I14=0,"",H14/I14) | K14: =IF(I14=0,"",J14*(1+$B$8)/(1-Reglages!$B$5)) | L14: =I14*$B$9 | M14: =IF(I14=0,"",L14-H14) | N14: =IF(OR(I14=0,B14=""),"",K14/B14-1)
A15: 3 | B15: =IF(3>Reglages!$G$16,"",$B$4*(1-Reglages!$I$16*2)) | C15: =IF(3>Reglages!$G$16,"",$B$5*Reglages!$H$16^2/SUMPRODUCT(Reglages!$H$16^(ROW(INDIRECT("1:"&Reglages!$G$16))-1))) | G15: =IF(OR(D15<>1,E15="",E15=0),0,F15/E15*(1-Reglages!$B$5)) | H15: =SUM($F$13:F15) | I15: =SUM($G$13:G15) | J15: =IF(I15=0,"",H15/I15) | K15: =IF(I15=0,"",J15*(1+$B$8)/(1-Reglages!$B$5)) | L15: =I15*$B$9 | M15: =IF(I15=0,"",L15-H15) | N15: =IF(OR(I15=0,B15=""),"",K15/B15-1)
A16: 4 | B16: =IF(4>Reglages!$G$16,"",$B$4*(1-Reglages!$I$16*3)) | C16: =IF(4>Reglages!$G$16,"",$B$5*Reglages!$H$16^3/SUMPRODUCT(Reglages!$H$16^(ROW(INDIRECT("1:"&Reglages!$G$16))-1))) | G16: =IF(OR(D16<>1,E16="",E16=0),0,F16/E16*(1-Reglages!$B$5)) | H16: =SUM($F$13:F16) | I16: =SUM($G$13:G16) | J16: =IF(I16=0,"",H16/I16) | K16: =IF(I16=0,"",J16*(1+$B$8)/(1-Reglages!$B$5)) | L16: =I16*$B$9 | M16: =IF(I16=0,"",L16-H16) | N16: =IF(OR(I16=0,B16=""),"",K16/B16-1)
A17: 5 | B17: =IF(5>Reglages!$G$16,"",$B$4*(1-Reglages!$I$16*4)) | C17: =IF(5>Reglages!$G$16,"",$B$5*Reglages!$H$16^4/SUMPRODUCT(Reglages!$H$16^(ROW(INDIRECT("1:"&Reglages!$G$16))-1))) | G17: =IF(OR(D17<>1,E17="",E17=0),0,F17/E17*(1-Reglages!$B$5)) | H17: =SUM($F$13:F17) | I17: =SUM($G$13:G17) | J17: =IF(I17=0,"",H17/I17) | K17: =IF(I17=0,"",J17*(1+$B$8)/(1-Reglages!$B$5)) | L17: =I17*$B$9 | M17: =IF(I17=0,"",L17-H17) | N17: =IF(OR(I17=0,B17=""),"",K17/B17-1)
A18: 6 | B18: =IF(6>Reglages!$G$16,"",$B$4*(1-Reglages!$I$16*5)) | C18: =IF(6>Reglages!$G$16,"",$B$5*Reglages!$H$16^5/SUMPRODUCT(Reglages!$H$16^(ROW(INDIRECT("1:"&Reglages!$G$16))-1))) | G18: =IF(OR(D18<>1,E18="",E18=0),0,F18/E18*(1-Reglages!$B$5)) | H18: =SUM($F$13:F18) | I18: =SUM($G$13:G18) | J18: =IF(I18=0,"",H18/I18) | K18: =IF(I18=0,"",J18*(1+$B$8)/(1-Reglages!$B$5)) | L18: =I18*$B$9 | M18: =IF(I18=0,"",L18-H18) | N18: =IF(OR(I18=0,B18=""),"",K18/B18-1)
A19: 7 | B19: =IF(7>Reglages!$G$16,"",$B$4*(1-Reglages!$I$16*6)) | C19: =IF(7>Reglages!$G$16,"",$B$5*Reglages!$H$16^6/SUMPRODUCT(Reglages!$H$16^(ROW(INDIRECT("1:"&Reglages!$G$16))-1))) | G19: =IF(OR(D19<>1,E19="",E19=0),0,F19/E19*(1-Reglages!$B$5)) | H19: =SUM($F$13:F19) | I19: =SUM($G$13:G19) | J19: =IF(I19=0,"",H19/I19) | K19: =IF(I19=0,"",J19*(1+$B$8)/(1-Reglages!$B$5)) | L19: =I19*$B$9 | M19: =IF(I19=0,"",L19-H19) | N19: =IF(OR(I19=0,B19=""),"",K19/B19-1)
A20: 8 | B20: =IF(8>Reglages!$G$16,"",$B$4*(1-Reglages!$I$16*7)) | C20: =IF(8>Reglages!$G$16,"",$B$5*Reglages!$H$16^7/SUMPRODUCT(Reglages!$H$16^(ROW(INDIRECT("1:"&Reglages!$G$16))-1))) | G20: =IF(OR(D20<>1,E20="",E20=0),0,F20/E20*(1-Reglages!$B$5)) | H20: =SUM($F$13:F20) | I20: =SUM($G$13:G20) | J20: =IF(I20=0,"",H20/I20) | K20: =IF(I20=0,"",J20*(1+$B$8)/(1-Reglages!$B$5)) | L20: =I20*$B$9 | M20: =IF(I20=0,"",L20-H20) | N20: =IF(OR(I20=0,B20=""),"",K20/B20-1)
A21: 9 | B21: =IF(9>Reglages!$G$16,"",$B$4*(1-Reglages!$I$16*8)) | C21: =IF(9>Reglages!$G$16,"",$B$5*Reglages!$H$16^8/SUMPRODUCT(Reglages!$H$16^(ROW(INDIRECT("1:"&Reglages!$G$16))-1))) | G21: =IF(OR(D21<>1,E21="",E21=0),0,F21/E21*(1-Reglages!$B$5)) | H21: =SUM($F$13:F21) | I21: =SUM($G$13:G21) | J21: =IF(I21=0,"",H21/I21) | K21: =IF(I21=0,"",J21*(1+$B$8)/(1-Reglages!$B$5)) | L21: =I21*$B$9 | M21: =IF(I21=0,"",L21-H21) | N21: =IF(OR(I21=0,B21=""),"",K21/B21-1)
A22: 10 | B22: =IF(10>Reglages!$G$16,"",$B$4*(1-Reglages!$I$16*9)) | C22: =IF(10>Reglages!$G$16,"",$B$5*Reglages!$H$16^9/SUMPRODUCT(Reglages!$H$16^(ROW(INDIRECT("1:"&Reglages!$G$16))-1))) | G22: =IF(OR(D22<>1,E22="",E22=0),0,F22/E22*(1-Reglages!$B$5)) | H22: =SUM($F$13:F22) | I22: =SUM($G$13:G22) | J22: =IF(I22=0,"",H22/I22) | K22: =IF(I22=0,"",J22*(1+$B$8)/(1-Reglages!$B$5)) | L22: =I22*$B$9 | M22: =IF(I22=0,"",L22-H22) | N22: =IF(OR(I22=0,B22=""),"",K22/B22-1)
A23: 11 | B23: =IF(11>Reglages!$G$16,"",$B$4*(1-Reglages!$I$16*10)) | C23: =IF(11>Reglages!$G$16,"",$B$5*Reglages!$H$16^10/SUMPRODUCT(Reglages!$H$16^(ROW(INDIRECT("1:"&Reglages!$G$16))-1))) | G23: =IF(OR(D23<>1,E23="",E23=0),0,F23/E23*(1-Reglages!$B$5)) | H23: =SUM($F$13:F23) | I23: =SUM($G$13:G23) | J23: =IF(I23=0,"",H23/I23) | K23: =IF(I23=0,"",J23*(1+$B$8)/(1-Reglages!$B$5)) | L23: =I23*$B$9 | M23: =IF(I23=0,"",L23-H23) | N23: =IF(OR(I23=0,B23=""),"",K23/B23-1)
A24: 12 | B24: =IF(12>Reglages!$G$16,"",$B$4*(1-Reglages!$I$16*11)) | C24: =IF(12>Reglages!$G$16,"",$B$5*Reglages!$H$16^11/SUMPRODUCT(Reglages!$H$16^(ROW(INDIRECT("1:"&Reglages!$G$16))-1))) | G24: =IF(OR(D24<>1,E24="",E24=0),0,F24/E24*(1-Reglages!$B$5)) | H24: =SUM($F$13:F24) | I24: =SUM($G$13:G24) | J24: =IF(I24=0,"",H24/I24) | K24: =IF(I24=0,"",J24*(1+$B$8)/(1-Reglages!$B$5)) | L24: =I24*$B$9 | M24: =IF(I24=0,"",L24-H24) | N24: =IF(OR(I24=0,B24=""),"",K24/B24-1)
A25: 13 | B25: =IF(13>Reglages!$G$16,"",$B$4*(1-Reglages!$I$16*12)) | C25: =IF(13>Reglages!$G$16,"",$B$5*Reglages!$H$16^12/SUMPRODUCT(Reglages!$H$16^(ROW(INDIRECT("1:"&Reglages!$G$16))-1))) | G25: =IF(OR(D25<>1,E25="",E25=0),0,F25/E25*(1-Reglages!$B$5)) | H25: =SUM($F$13:F25) | I25: =SUM($G$13:G25) | J25: =IF(I25=0,"",H25/I25) | K25: =IF(I25=0,"",J25*(1+$B$8)/(1-Reglages!$B$5)) | L25: =I25*$B$9 | M25: =IF(I25=0,"",L25-H25) | N25: =IF(OR(I25=0,B25=""),"",K25/B25-1)
A26: 14 | B26: =IF(14>Reglages!$G$16,"",$B$4*(1-Reglages!$I$16*13)) | C26: =IF(14>Reglages!$G$16,"",$B$5*Reglages!$H$16^13/SUMPRODUCT(Reglages!$H$16^(ROW(INDIRECT("1:"&Reglages!$G$16))-1))) | G26: =IF(OR(D26<>1,E26="",E26=0),0,F26/E26*(1-Reglages!$B$5)) | H26: =SUM($F$13:F26) | I26: =SUM($G$13:G26) | J26: =IF(I26=0,"",H26/I26) | K26: =IF(I26=0,"",J26*(1+$B$8)/(1-Reglages!$B$5)) | L26: =I26*$B$9 | M26: =IF(I26=0,"",L26-H26) | N26: =IF(OR(I26=0,B26=""),"",K26/B26-1)
A27: TOTAL | C27: =SUM(C13:C26) | F27: =SUM(F13:F26) | G27: =SUM(G13:G26) | J27: =IF(G27=0,"",F27/G27) | K27: =IF(G27=0,"",J27*(1+$B$8)/(1-Reglages!$B$5)) | L27: =G27*$B$9 | M27: =IF(G27=0,"",L27-F27) | N27: =IF(OR(G27=0,$B$9=0),"",K27/$B$9-1)
A29: Si vous revendez tout maintenant au prix de revente | E29: =IF(G27=0,"",F27*$B$8)
A30: Etat de la descente | E30: =IF(G27=0,"pas commencee",IF($B$9<=$E$6,"ABANDON : sous le seuil",IF(AND($E$5<>"",$E$5>Reglages!$B$8),"BLOQUEE : trop longue",IF($B$9>=K27,"REVENDRE MAINTENANT",IF(COUNT(D13:D26)-COUNTIF(D13:D26,1)=0,"echelle epuisee","en cours"))))

Sheet DOGE
A1: Descente DOGE
A2: Colonnes jaunes : a remplir quand l'achat est passe. Le reste est calcule.
A4: Prix de reference | B4: =Reglages!B17 | D4: Date du premier achat
A5: Budget alloue | B5: =Reglages!E17 | D5: Jours ecoules | E5: =IF(E4="","",TODAY()-E4)
A6: Profondeur de l'echelle | B6: =Reglages!F17 | D6: Seuil d'abandon | E6: =B7*(1-0.15) | F6: 15 % sous le dernier palier. En dessous, on n'ajoute plus rien.
A7: Prix du dernier palier | B7: =Reglages!J17
A8: Objectif net a la revente | B8: =Reglages!B6
A9: Prix actuel du marche | B9: 0.08891
A12: Palier | B12: Prix cible | C12: Mise prevue (EUR) | D12: Fait ? (1 = oui) | E12: Prix reellement paye | F12: Montant reellement investi (EUR) | G12: Unites obtenues | H12: Cumul investi | I12: Cumul unites | J12: Prix de revient moyen | K12: Prix de revente (+2 % net) | L12: Valeur au prix actuel | M12: P&L latent | N12: Rebond requis depuis ce palier
A13: 1 | B13: =IF(1>Reglages!$G$17,"",$B$4*(1-Reglages!$I$17*0)) | C13: =IF(1>Reglages!$G$17,"",$B$5*Reglages!$H$17^0/SUMPRODUCT(Reglages!$H$17^(ROW(INDIRECT("1:"&Reglages!$G$17))-1))) | G13: =IF(OR(D13<>1,E13="",E13=0),0,F13/E13*(1-Reglages!$B$5)) | H13: =SUM($F$13:F13) | I13: =SUM($G$13:G13) | J13: =IF(I13=0,"",H13/I13) | K13: =IF(I13=0,"",J13*(1+$B$8)/(1-Reglages!$B$5)) | L13: =I13*$B$9 | M13: =IF(I13=0,"",L13-H13) | N13: =IF(OR(I13=0,B13=""),"",K13/B13-1)
A14: 2 | B14: =IF(2>Reglages!$G$17,"",$B$4*(1-Reglages!$I$17*1)) | C14: =IF(2>Reglages!$G$17,"",$B$5*Reglages!$H$17^1/SUMPRODUCT(Reglages!$H$17^(ROW(INDIRECT("1:"&Reglages!$G$17))-1))) | G14: =IF(OR(D14<>1,E14="",E14=0),0,F14/E14*(1-Reglages!$B$5)) | H14: =SUM($F$13:F14) | I14: =SUM($G$13:G14) | J14: =IF(I14=0,"",H14/I14) | K14: =IF(I14=0,"",J14*(1+$B$8)/(1-Reglages!$B$5)) | L14: =I14*$B$9 | M14: =IF(I14=0,"",L14-H14) | N14: =IF(OR(I14=0,B14=""),"",K14/B14-1)
A15: 3 | B15: =IF(3>Reglages!$G$17,"",$B$4*(1-Reglages!$I$17*2)) | C15: =IF(3>Reglages!$G$17,"",$B$5*Reglages!$H$17^2/SUMPRODUCT(Reglages!$H$17^(ROW(INDIRECT("1:"&Reglages!$G$17))-1))) | G15: =IF(OR(D15<>1,E15="",E15=0),0,F15/E15*(1-Reglages!$B$5)) | H15: =SUM($F$13:F15) | I15: =SUM($G$13:G15) | J15: =IF(I15=0,"",H15/I15) | K15: =IF(I15=0,"",J15*(1+$B$8)/(1-Reglages!$B$5)) | L15: =I15*$B$9 | M15: =IF(I15=0,"",L15-H15) | N15: =IF(OR(I15=0,B15=""),"",K15/B15-1)
A16: 4 | B16: =IF(4>Reglages!$G$17,"",$B$4*(1-Reglages!$I$17*3)) | C16: =IF(4>Reglages!$G$17,"",$B$5*Reglages!$H$17^3/SUMPRODUCT(Reglages!$H$17^(ROW(INDIRECT("1:"&Reglages!$G$17))-1))) | G16: =IF(OR(D16<>1,E16="",E16=0),0,F16/E16*(1-Reglages!$B$5)) | H16: =SUM($F$13:F16) | I16: =SUM($G$13:G16) | J16: =IF(I16=0,"",H16/I16) | K16: =IF(I16=0,"",J16*(1+$B$8)/(1-Reglages!$B$5)) | L16: =I16*$B$9 | M16: =IF(I16=0,"",L16-H16) | N16: =IF(OR(I16=0,B16=""),"",K16/B16-1)
A17: 5 | B17: =IF(5>Reglages!$G$17,"",$B$4*(1-Reglages!$I$17*4)) | C17: =IF(5>Reglages!$G$17,"",$B$5*Reglages!$H$17^4/SUMPRODUCT(Reglages!$H$17^(ROW(INDIRECT("1:"&Reglages!$G$17))-1))) | G17: =IF(OR(D17<>1,E17="",E17=0),0,F17/E17*(1-Reglages!$B$5)) | H17: =SUM($F$13:F17) | I17: =SUM($G$13:G17) | J17: =IF(I17=0,"",H17/I17) | K17: =IF(I17=0,"",J17*(1+$B$8)/(1-Reglages!$B$5)) | L17: =I17*$B$9 | M17: =IF(I17=0,"",L17-H17) | N17: =IF(OR(I17=0,B17=""),"",K17/B17-1)
A18: 6 | B18: =IF(6>Reglages!$G$17,"",$B$4*(1-Reglages!$I$17*5)) | C18: =IF(6>Reglages!$G$17,"",$B$5*Reglages!$H$17^5/SUMPRODUCT(Reglages!$H$17^(ROW(INDIRECT("1:"&Reglages!$G$17))-1))) | G18: =IF(OR(D18<>1,E18="",E18=0),0,F18/E18*(1-Reglages!$B$5)) | H18: =SUM($F$13:F18) | I18: =SUM($G$13:G18) | J18: =IF(I18=0,"",H18/I18) | K18: =IF(I18=0,"",J18*(1+$B$8)/(1-Reglages!$B$5)) | L18: =I18*$B$9 | M18: =IF(I18=0,"",L18-H18) | N18: =IF(OR(I18=0,B18=""),"",K18/B18-1)
A19: 7 | B19: =IF(7>Reglages!$G$17,"",$B$4*(1-Reglages!$I$17*6)) | C19: =IF(7>Reglages!$G$17,"",$B$5*Reglages!$H$17^6/SUMPRODUCT(Reglages!$H$17^(ROW(INDIRECT("1:"&Reglages!$G$17))-1))) | G19: =IF(OR(D19<>1,E19="",E19=0),0,F19/E19*(1-Reglages!$B$5)) | H19: =SUM($F$13:F19) | I19: =SUM($G$13:G19) | J19: =IF(I19=0,"",H19/I19) | K19: =IF(I19=0,"",J19*(1+$B$8)/(1-Reglages!$B$5)) | L19: =I19*$B$9 | M19: =IF(I19=0,"",L19-H19) | N19: =IF(OR(I19=0,B19=""),"",K19/B19-1)
A20: 8 | B20: =IF(8>Reglages!$G$17,"",$B$4*(1-Reglages!$I$17*7)) | C20: =IF(8>Reglages!$G$17,"",$B$5*Reglages!$H$17^7/SUMPRODUCT(Reglages!$H$17^(ROW(INDIRECT("1:"&Reglages!$G$17))-1))) | G20: =IF(OR(D20<>1,E20="",E20=0),0,F20/E20*(1-Reglages!$B$5)) | H20: =SUM($F$13:F20) | I20: =SUM($G$13:G20) | J20: =IF(I20=0,"",H20/I20) | K20: =IF(I20=0,"",J20*(1+$B$8)/(1-Reglages!$B$5)) | L20: =I20*$B$9 | M20: =IF(I20=0,"",L20-H20) | N20: =IF(OR(I20=0,B20=""),"",K20/B20-1)
A21: 9 | B21: =IF(9>Reglages!$G$17,"",$B$4*(1-Reglages!$I$17*8)) | C21: =IF(9>Reglages!$G$17,"",$B$5*Reglages!$H$17^8/SUMPRODUCT(Reglages!$H$17^(ROW(INDIRECT("1:"&Reglages!$G$17))-1))) | G21: =IF(OR(D21<>1,E21="",E21=0),0,F21/E21*(1-Reglages!$B$5)) | H21: =SUM($F$13:F21) | I21: =SUM($G$13:G21) | J21: =IF(I21=0,"",H21/I21) | K21: =IF(I21=0,"",J21*(1+$B$8)/(1-Reglages!$B$5)) | L21: =I21*$B$9 | M21: =IF(I21=0,"",L21-H21) | N21: =IF(OR(I21=0,B21=""),"",K21/B21-1)
A22: 10 | B22: =IF(10>Reglages!$G$17,"",$B$4*(1-Reglages!$I$17*9)) | C22: =IF(10>Reglages!$G$17,"",$B$5*Reglages!$H$17^9/SUMPRODUCT(Reglages!$H$17^(ROW(INDIRECT("1:"&Reglages!$G$17))-1))) | G22: =IF(OR(D22<>1,E22="",E22=0),0,F22/E22*(1-Reglages!$B$5)) | H22: =SUM($F$13:F22) | I22: =SUM($G$13:G22) | J22: =IF(I22=0,"",H22/I22) | K22: =IF(I22=0,"",J22*(1+$B$8)/(1-Reglages!$B$5)) | L22: =I22*$B$9 | M22: =IF(I22=0,"",L22-H22) | N22: =IF(OR(I22=0,B22=""),"",K22/B22-1)
A23: 11 | B23: =IF(11>Reglages!$G$17,"",$B$4*(1-Reglages!$I$17*10)) | C23: =IF(11>Reglages!$G$17,"",$B$5*Reglages!$H$17^10/SUMPRODUCT(Reglages!$H$17^(ROW(INDIRECT("1:"&Reglages!$G$17))-1))) | G23: =IF(OR(D23<>1,E23="",E23=0),0,F23/E23*(1-Reglages!$B$5)) | H23: =SUM($F$13:F23) | I23: =SUM($G$13:G23) | J23: =IF(I23=0,"",H23/I23) | K23: =IF(I23=0,"",J23*(1+$B$8)/(1-Reglages!$B$5)) | L23: =I23*$B$9 | M23: =IF(I23=0,"",L23-H23) | N23: =IF(OR(I23=0,B23=""),"",K23/B23-1)
A24: 12 | B24: =IF(12>Reglages!$G$17,"",$B$4*(1-Reglages!$I$17*11)) | C24: =IF(12>Reglages!$G$17,"",$B$5*Reglages!$H$17^11/SUMPRODUCT(Reglages!$H$17^(ROW(INDIRECT("1:"&Reglages!$G$17))-1))) | G24: =IF(OR(D24<>1,E24="",E24=0),0,F24/E24*(1-Reglages!$B$5)) | H24: =SUM($F$13:F24) | I24: =SUM($G$13:G24) | J24: =IF(I24=0,"",H24/I24) | K24: =IF(I24=0,"",J24*(1+$B$8)/(1-Reglages!$B$5)) | L24: =I24*$B$9 | M24: =IF(I24=0,"",L24-H24) | N24: =IF(OR(I24=0,B24=""),"",K24/B24-1)
A25: 13 | B25: =IF(13>Reglages!$G$17,"",$B$4*(1-Reglages!$I$17*12)) | C25: =IF(13>Reglages!$G$17,"",$B$5*Reglages!$H$17^12/SUMPRODUCT(Reglages!$H$17^(ROW(INDIRECT("1:"&Reglages!$G$17))-1))) | G25: =IF(OR(D25<>1,E25="",E25=0),0,F25/E25*(1-Reglages!$B$5)) | H25: =SUM($F$13:F25) | I25: =SUM($G$13:G25) | J25: =IF(I25=0,"",H25/I25) | K25: =IF(I25=0,"",J25*(1+$B$8)/(1-Reglages!$B$5)) | L25: =I25*$B$9 | M25: =IF(I25=0,"",L25-H25) | N25: =IF(OR(I25=0,B25=""),"",K25/B25-1)
A26: 14 | B26: =IF(14>Reglages!$G$17,"",$B$4*(1-Reglages!$I$17*13)) | C26: =IF(14>Reglages!$G$17,"",$B$5*Reglages!$H$17^13/SUMPRODUCT(Reglages!$H$17^(ROW(INDIRECT("1:"&Reglages!$G$17))-1))) | G26: =IF(OR(D26<>1,E26="",E26=0),0,F26/E26*(1-Reglages!$B$5)) | H26: =SUM($F$13:F26) | I26: =SUM($G$13:G26) | J26: =IF(I26=0,"",H26/I26) | K26: =IF(I26=0,"",J26*(1+$B$8)/(1-Reglages!$B$5)) | L26: =I26*$B$9 | M26: =IF(I26=0,"",L26-H26) | N26: =IF(OR(I26=0,B26=""),"",K26/B26-1)
A27: TOTAL | C27: =SUM(C13:C26) | F27: =SUM(F13:F26) | G27: =SUM(G13:G26) | J27: =IF(G27=0,"",F27/G27) | K27: =IF(G27=0,"",J27*(1+$B$8)/(1-Reglages!$B$5)) | L27: =G27*$B$9 | M27: =IF(G27=0,"",L27-F27) | N27: =IF(OR(G27=0,$B$9=0),"",K27/$B$9-1)
A29: Si vous revendez tout maintenant au prix de revente | E29: =IF(G27=0,"",F27*$B$8)
A30: Etat de la descente | E30: =IF(G27=0,"pas commencee",IF($B$9<=$E$6,"ABANDON : sous le seuil",IF(AND($E$5<>"",$E$5>Reglages!$B$8),"BLOQUEE : trop longue",IF($B$9>=K27,"REVENDRE MAINTENANT",IF(COUNT(D13:D26)-COUNTIF(D13:D26,1)=0,"echelle epuisee","en cours"))))

Sheet ETH
A1: Descente ETH
A2: Colonnes jaunes : a remplir quand l'achat est passe. Le reste est calcule.
A4: Prix de reference | B4: =Reglages!B18 | D4: Date du premier achat
A5: Budget alloue | B5: =Reglages!E18 | D5: Jours ecoules | E5: =IF(E4="","",TODAY()-E4)
A6: Profondeur de l'echelle | B6: =Reglages!F18 | D6: Seuil d'abandon | E6: =B7*(1-0.15) | F6: 15 % sous le dernier palier. En dessous, on n'ajoute plus rien.
A7: Prix du dernier palier | B7: =Reglages!J18
A8: Objectif net a la revente | B8: =Reglages!B6
A9: Prix actuel du marche | B9: 2484.1
A12: Palier | B12: Prix cible | C12: Mise prevue (EUR) | D12: Fait ? (1 = oui) | E12: Prix reellement paye | F12: Montant reellement investi (EUR) | G12: Unites obtenues | H12: Cumul investi | I12: Cumul unites | J12: Prix de revient moyen | K12: Prix de revente (+2 % net) | L12: Valeur au prix actuel | M12: P&L latent | N12: Rebond requis depuis ce palier
A13: 1 | B13: =IF(1>Reglages!$G$18,"",$B$4*(1-Reglages!$I$18*0)) | C13: =IF(1>Reglages!$G$18,"",$B$5*Reglages!$H$18^0/SUMPRODUCT(Reglages!$H$18^(ROW(INDIRECT("1:"&Reglages!$G$18))-1))) | G13: =IF(OR(D13<>1,E13="",E13=0),0,F13/E13*(1-Reglages!$B$5)) | H13: =SUM($F$13:F13) | I13: =SUM($G$13:G13) | J13: =IF(I13=0,"",H13/I13) | K13: =IF(I13=0,"",J13*(1+$B$8)/(1-Reglages!$B$5)) | L13: =I13*$B$9 | M13: =IF(I13=0,"",L13-H13) | N13: =IF(OR(I13=0,B13=""),"",K13/B13-1)
A14: 2 | B14: =IF(2>Reglages!$G$18,"",$B$4*(1-Reglages!$I$18*1)) | C14: =IF(2>Reglages!$G$18,"",$B$5*Reglages!$H$18^1/SUMPRODUCT(Reglages!$H$18^(ROW(INDIRECT("1:"&Reglages!$G$18))-1))) | G14: =IF(OR(D14<>1,E14="",E14=0),0,F14/E14*(1-Reglages!$B$5)) | H14: =SUM($F$13:F14) | I14: =SUM($G$13:G14) | J14: =IF(I14=0,"",H14/I14) | K14: =IF(I14=0,"",J14*(1+$B$8)/(1-Reglages!$B$5)) | L14: =I14*$B$9 | M14: =IF(I14=0,"",L14-H14) | N14: =IF(OR(I14=0,B14=""),"",K14/B14-1)
A15: 3 | B15: =IF(3>Reglages!$G$18,"",$B$4*(1-Reglages!$I$18*2)) | C15: =IF(3>Reglages!$G$18,"",$B$5*Reglages!$H$18^2/SUMPRODUCT(Reglages!$H$18^(ROW(INDIRECT("1:"&Reglages!$G$18))-1))) | G15: =IF(OR(D15<>1,E15="",E15=0),0,F15/E15*(1-Reglages!$B$5)) | H15: =SUM($F$13:F15) | I15: =SUM($G$13:G15) | J15: =IF(I15=0,"",H15/I15) | K15: =IF(I15=0,"",J15*(1+$B$8)/(1-Reglages!$B$5)) | L15: =I15*$B$9 | M15: =IF(I15=0,"",L15-H15) | N15: =IF(OR(I15=0,B15=""),"",K15/B15-1)
A16: 4 | B16: =IF(4>Reglages!$G$18,"",$B$4*(1-Reglages!$I$18*3)) | C16: =IF(4>Reglages!$G$18,"",$B$5*Reglages!$H$18^3/SUMPRODUCT(Reglages!$H$18^(ROW(INDIRECT("1:"&Reglages!$G$18))-1))) | G16: =IF(OR(D16<>1,E16="",E16=0),0,F16/E16*(1-Reglages!$B$5)) | H16: =SUM($F$13:F16) | I16: =SUM($G$13:G16) | J16: =IF(I16=0,"",H16/I16) | K16: =IF(I16=0,"",J16*(1+$B$8)/(1-Reglages!$B$5)) | L16: =I16*$B$9 | M16: =IF(I16=0,"",L16-H16) | N16: =IF(OR(I16=0,B16=""),"",K16/B16-1)
A17: 5 | B17: =IF(5>Reglages!$G$18,"",$B$4*(1-Reglages!$I$18*4)) | C17: =IF(5>Reglages!$G$18,"",$B$5*Reglages!$H$18^4/SUMPRODUCT(Reglages!$H$18^(ROW(INDIRECT("1:"&Reglages!$G$18))-1))) | G17: =IF(OR(D17<>1,E17="",E17=0),0,F17/E17*(1-Reglages!$B$5)) | H17: =SUM($F$13:F17) | I17: =SUM($G$13:G17) | J17: =IF(I17=0,"",H17/I17) | K17: =IF(I17=0,"",J17*(1+$B$8)/(1-Reglages!$B$5)) | L17: =I17*$B$9 | M17: =IF(I17=0,"",L17-H17) | N17: =IF(OR(I17=0,B17=""),"",K17/B17-1)
A18: 6 | B18: =IF(6>Reglages!$G$18,"",$B$4*(1-Reglages!$I$18*5)) | C18: =IF(6>Reglages!$G$18,"",$B$5*Reglages!$H$18^5/SUMPRODUCT(Reglages!$H$18^(ROW(INDIRECT("1:"&Reglages!$G$18))-1))) | G18: =IF(OR(D18<>1,E18="",E18=0),0,F18/E18*(1-Reglages!$B$5)) | H18: =SUM($F$13:F18) | I18: =SUM($G$13:G18) | J18: =IF(I18=0,"",H18/I18) | K18: =IF(I18=0,"",J18*(1+$B$8)/(1-Reglages!$B$5)) | L18: =I18*$B$9 | M18: =IF(I18=0,"",L18-H18) | N18: =IF(OR(I18=0,B18=""),"",K18/B18-1)
A19: 7 | B19: =IF(7>Reglages!$G$18,"",$B$4*(1-Reglages!$I$18*6)) | C19: =IF(7>Reglages!$G$18,"",$B$5*Reglages!$H$18^6/SUMPRODUCT(Reglages!$H$18^(ROW(INDIRECT("1:"&Reglages!$G$18))-1))) | G19: =IF(OR(D19<>1,E19="",E19=0),0,F19/E19*(1-Reglages!$B$5)) | H19: =SUM($F$13:F19) | I19: =SUM($G$13:G19) | J19: =IF(I19=0,"",H19/I19) | K19: =IF(I19=0,"",J19*(1+$B$8)/(1-Reglages!$B$5)) | L19: =I19*$B$9 | M19: =IF(I19=0,"",L19-H19) | N19: =IF(OR(I19=0,B19=""),"",K19/B19-1)
A20: 8 | B20: =IF(8>Reglages!$G$18,"",$B$4*(1-Reglages!$I$18*7)) | C20: =IF(8>Reglages!$G$18,"",$B$5*Reglages!$H$18^7/SUMPRODUCT(Reglages!$H$18^(ROW(INDIRECT("1:"&Reglages!$G$18))-1))) | G20: =IF(OR(D20<>1,E20="",E20=0),0,F20/E20*(1-Reglages!$B$5)) | H20: =SUM($F$13:F20) | I20: =SUM($G$13:G20) | J20: =IF(I20=0,"",H20/I20) | K20: =IF(I20=0,"",J20*(1+$B$8)/(1-Reglages!$B$5)) | L20: =I20*$B$9 | M20: =IF(I20=0,"",L20-H20) | N20: =IF(OR(I20=0,B20=""),"",K20/B20-1)
A21: 9 | B21: =IF(9>Reglages!$G$18,"",$B$4*(1-Reglages!$I$18*8)) | C21: =IF(9>Reglages!$G$18,"",$B$5*Reglages!$H$18^8/SUMPRODUCT(Reglages!$H$18^(ROW(INDIRECT("1:"&Reglages!$G$18))-1))) | G21: =IF(OR(D21<>1,E21="",E21=0),0,F21/E21*(1-Reglages!$B$5)) | H21: =SUM($F$13:F21) | I21: =SUM($G$13:G21) | J21: =IF(I21=0,"",H21/I21) | K21: =IF(I21=0,"",J21*(1+$B$8)/(1-Reglages!$B$5)) | L21: =I21*$B$9 | M21: =IF(I21=0,"",L21-H21) | N21: =IF(OR(I21=0,B21=""),"",K21/B21-1)
A22: 10 | B22: =IF(10>Reglages!$G$18,"",$B$4*(1-Reglages!$I$18*9)) | C22: =IF(10>Reglages!$G$18,"",$B$5*Reglages!$H$18^9/SUMPRODUCT(Reglages!$H$18^(ROW(INDIRECT("1:"&Reglages!$G$18))-1))) | G22: =IF(OR(D22<>1,E22="",E22=0),0,F22/E22*(1-Reglages!$B$5)) | H22: =SUM($F$13:F22) | I22: =SUM($G$13:G22) | J22: =IF(I22=0,"",H22/I22) | K22: =IF(I22=0,"",J22*(1+$B$8)/(1-Reglages!$B$5)) | L22: =I22*$B$9 | M22: =IF(I22=0,"",L22-H22) | N22: =IF(OR(I22=0,B22=""),"",K22/B22-1)
A23: 11 | B23: =IF(11>Reglages!$G$18,"",$B$4*(1-Reglages!$I$18*10)) | C23: =IF(11>Reglages!$G$18,"",$B$5*Reglages!$H$18^10/SUMPRODUCT(Reglages!$H$18^(ROW(INDIRECT("1:"&Reglages!$G$18))-1))) | G23: =IF(OR(D23<>1,E23="",E23=0),0,F23/E23*(1-Reglages!$B$5)) | H23: =SUM($F$13:F23) | I23: =SUM($G$13:G23) | J23: =IF(I23=0,"",H23/I23) | K23: =IF(I23=0,"",J23*(1+$B$8)/(1-Reglages!$B$5)) | L23: =I23*$B$9 | M23: =IF(I23=0,"",L23-H23) | N23: =IF(OR(I23=0,B23=""),"",K23/B23-1)
A24: 12 | B24: =IF(12>Reglages!$G$18,"",$B$4*(1-Reglages!$I$18*11)) | C24: =IF(12>Reglages!$G$18,"",$B$5*Reglages!$H$18^11/SUMPRODUCT(Reglages!$H$18^(ROW(INDIRECT("1:"&Reglages!$G$18))-1))) | G24: =IF(OR(D24<>1,E24="",E24=0),0,F24/E24*(1-Reglages!$B$5)) | H24: =SUM($F$13:F24) | I24: =SUM($G$13:G24) | J24: =IF(I24=0,"",H24/I24) | K24: =IF(I24=0,"",J24*(1+$B$8)/(1-Reglages!$B$5)) | L24: =I24*$B$9 | M24: =IF(I24=0,"",L24-H24) | N24: =IF(OR(I24=0,B24=""),"",K24/B24-1)
A25: 13 | B25: =IF(13>Reglages!$G$18,"",$B$4*(1-Reglages!$I$18*12)) | C25: =IF(13>Reglages!$G$18,"",$B$5*Reglages!$H$18^12/SUMPRODUCT(Reglages!$H$18^(ROW(INDIRECT("1:"&Reglages!$G$18))-1))) | G25: =IF(OR(D25<>1,E25="",E25=0),0,F25/E25*(1-Reglages!$B$5)) | H25: =SUM($F$13:F25) | I25: =SUM($G$13:G25) | J25: =IF(I25=0,"",H25/I25) | K25: =IF(I25=0,"",J25*(1+$B$8)/(1-Reglages!$B$5)) | L25: =I25*$B$9 | M25: =IF(I25=0,"",L25-H25) | N25: =IF(OR(I25=0,B25=""),"",K25/B25-1)
A26: 14 | B26: =IF(14>Reglages!$G$18,"",$B$4*(1-Reglages!$I$18*13)) | C26: =IF(14>Reglages!$G$18,"",$B$5*Reglages!$H$18^13/SUMPRODUCT(Reglages!$H$18^(ROW(INDIRECT("1:"&Reglages!$G$18))-1))) | G26: =IF(OR(D26<>1,E26="",E26=0),0,F26/E26*(1-Reglages!$B$5)) | H26: =SUM($F$13:F26) | I26: =SUM($G$13:G26) | J26: =IF(I26=0,"",H26/I26) | K26: =IF(I26=0,"",J26*(1+$B$8)/(1-Reglages!$B$5)) | L26: =I26*$B$9 | M26: =IF(I26=0,"",L26-H26) | N26: =IF(OR(I26=0,B26=""),"",K26/B26-1)
A27: TOTAL | C27: =SUM(C13:C26) | F27: =SUM(F13:F26) | G27: =SUM(G13:G26) | J27: =IF(G27=0,"",F27/G27) | K27: =IF(G27=0,"",J27*(1+$B$8)/(1-Reglages!$B$5)) | L27: =G27*$B$9 | M27: =IF(G27=0,"",L27-F27) | N27: =IF(OR(G27=0,$B$9=0),"",K27/$B$9-1)
A29: Si vous revendez tout maintenant au prix de revente | E29: =IF(G27=0,"",F27*$B$8)
A30: Etat de la descente | E30: =IF(G27=0,"pas commencee",IF($B$9<=$E$6,"ABANDON : sous le seuil",IF(AND($E$5<>"",$E$5>Reglages!$B$8),"BLOQUEE : trop longue",IF($B$9>=K27,"REVENDRE MAINTENANT",IF(COUNT(D13:D26)-COUNTIF(D13:D26,1)=0,"echelle epuisee","en cours"))))

Sheet TRX
A1: Descente TRX
A2: Colonnes jaunes : a remplir quand l'achat est passe. Le reste est calcule.
A4: Prix de reference | B4: =Reglages!B19 | D4: Date du premier achat
A5: Budget alloue | B5: =Reglages!E19 | D5: Jours ecoules | E5: =IF(E4="","",TODAY()-E4)
A6: Profondeur de l'echelle | B6: =Reglages!F19 | D6: Seuil d'abandon | E6: =B7*(1-0.15) | F6: 15 % sous le dernier palier. En dessous, on n'ajoute plus rien.
A7: Prix du dernier palier | B7: =Reglages!J19
A8: Objectif net a la revente | B8: =Reglages!B6
A9: Prix actuel du marche | B9: 0.3351
A12: Palier | B12: Prix cible | C12: Mise prevue (EUR) | D12: Fait ? (1 = oui) | E12: Prix reellement paye | F12: Montant reellement investi (EUR) | G12: Unites obtenues | H12: Cumul investi | I12: Cumul unites | J12: Prix de revient moyen | K12: Prix de revente (+2 % net) | L12: Valeur au prix actuel | M12: P&L latent | N12: Rebond requis depuis ce palier
A13: 1 | B13: =IF(1>Reglages!$G$19,"",$B$4*(1-Reglages!$I$19*0)) | C13: =IF(1>Reglages!$G$19,"",$B$5*Reglages!$H$19^0/SUMPRODUCT(Reglages!$H$19^(ROW(INDIRECT("1:"&Reglages!$G$19))-1))) | G13: =IF(OR(D13<>1,E13="",E13=0),0,F13/E13*(1-Reglages!$B$5)) | H13: =SUM($F$13:F13) | I13: =SUM($G$13:G13) | J13: =IF(I13=0,"",H13/I13) | K13: =IF(I13=0,"",J13*(1+$B$8)/(1-Reglages!$B$5)) | L13: =I13*$B$9 | M13: =IF(I13=0,"",L13-H13) | N13: =IF(OR(I13=0,B13=""),"",K13/B13-1)
A14: 2 | B14: =IF(2>Reglages!$G$19,"",$B$4*(1-Reglages!$I$19*1)) | C14: =IF(2>Reglages!$G$19,"",$B$5*Reglages!$H$19^1/SUMPRODUCT(Reglages!$H$19^(ROW(INDIRECT("1:"&Reglages!$G$19))-1))) | G14: =IF(OR(D14<>1,E14="",E14=0),0,F14/E14*(1-Reglages!$B$5)) | H14: =SUM($F$13:F14) | I14: =SUM($G$13:G14) | J14: =IF(I14=0,"",H14/I14) | K14: =IF(I14=0,"",J14*(1+$B$8)/(1-Reglages!$B$5)) | L14: =I14*$B$9 | M14: =IF(I14=0,"",L14-H14) | N14: =IF(OR(I14=0,B14=""),"",K14/B14-1)
A15: 3 | B15: =IF(3>Reglages!$G$19,"",$B$4*(1-Reglages!$I$19*2)) | C15: =IF(3>Reglages!$G$19,"",$B$5*Reglages!$H$19^2/SUMPRODUCT(Reglages!$H$19^(ROW(INDIRECT("1:"&Reglages!$G$19))-1))) | G15: =IF(OR(D15<>1,E15="",E15=0),0,F15/E15*(1-Reglages!$B$5)) | H15: =SUM($F$13:F15) | I15: =SUM($G$13:G15) | J15: =IF(I15=0,"",H15/I15) | K15: =IF(I15=0,"",J15*(1+$B$8)/(1-Reglages!$B$5)) | L15: =I15*$B$9 | M15: =IF(I15=0,"",L15-H15) | N15: =IF(OR(I15=0,B15=""),"",K15/B15-1)
A16: 4 | B16: =IF(4>Reglages!$G$19,"",$B$4*(1-Reglages!$I$19*3)) | C16: =IF(4>Reglages!$G$19,"",$B$5*Reglages!$H$19^3/SUMPRODUCT(Reglages!$H$19^(ROW(INDIRECT("1:"&Reglages!$G$19))-1))) | G16: =IF(OR(D16<>1,E16="",E16=0),0,F16/E16*(1-Reglages!$B$5)) | H16: =SUM($F$13:F16) | I16: =SUM($G$13:G16) | J16: =IF(I16=0,"",H16/I16) | K16: =IF(I16=0,"",J16*(1+$B$8)/(1-Reglages!$B$5)) | L16: =I16*$B$9 | M16: =IF(I16=0,"",L16-H16) | N16: =IF(OR(I16=0,B16=""),"",K16/B16-1)
